try {
    throw 'Houve um erro'
} catch {
    console.log('Chegamos at√© aqui')
}